<?xml version="1.0"?>
<sdf version="1.6">
  <model name="robotika_freyja_sensor_config_2">
    <pose>0 0 0.1275 0 0 0</pose>
    <enable_wind>1</enable_wind>
    <link name="base_link">
    <!-- Mass modelled as solid 0.3 x 0.24 x 0.08 cuboid at central
         bottom part of the robot, where battery and onboard computer
         are located, surrounded by ventilation space and lightweight
         chassis.
         Note: Most of the mass of the robot is *not* in the main body,
               but in wheels, which contain hub motors.
         https://en.wikipedia.org/wiki/List_of_moments_of_inertia
    -->
      <inertial>
        <pose>0 0 0.0725 0 0 0</pose>
        <mass>9.6</mass>
        <inertia>
          <ixx>0.0512</ixx>
          <iyy>0.07712</iyy>
          <izz>0.11808</izz>
        </inertia>
      </inertial>
  
      <!-- This bounding box covers also wheel mounts at the bottom and
           lidars on the top. -->
      <collision name="chassis_collision">
        <pose>0 0 0.105 0 0 0</pose>
        <geometry>
          <box>
            <size>0.50 0.24 0.235</size>
          </box>
        </geometry>
      </collision>
  
      <!-- <visual name="chassis_main_visual">
        <pose>0 0 0.0725 0 0 0</pose>
        <geometry>
          <box>
            <size>0.46 0.24 0.12</size>
          </box>
        </geometry>
        <material>
          <ambient>0.8706 0.7216 0.5294 1.0</ambient>
          <diffuse>0.8706 0.7216 0.5294 1.0</diffuse>
        </material>
      </visual> -->
      <visual name="visual">
        <pose>0 0 .1 0 0 1.5707</pose>
        <geometry>
          <mesh>
            <uri>model://T90_1/meshes/T90_1.dae</uri>
          </mesh>
        </geometry>
        <material>
          <script>
            <uri>model://T90_1/materials/scripts</uri>
            <uri>model://T90_1/materials/textures</uri>
            <name>ArucoVisualMarker0/Marker</name>
          </script>
          <ambient>1 1 1 1</ambient>
          <diffuse>1 1 1 1</diffuse>
          <specular>0 0 0 1</specular>
          <emissive>1 1 1 0</emissive>
          <shader type='vertex'>
            <normal_map>__default__</normal_map>
          </shader>
        </material>
      </visual>
      <!-- <visual name="chassis_front_face_bottom">
        <pose>0.24 0 0.0175 0 0 0</pose>
        <geometry>
          <box>
            <size>0.02001 0.24 0.01</size>
          </box>
        </geometry>
        <material>
          <ambient>0.8706 0.7216 0.5294 1.0</ambient>
          <diffuse>0.8706 0.7216 0.5294 1.0</diffuse>
        </material>
      </visual>
      <visual name="chassis_front_face_top">
        <pose>0.24 0 0.1275 0 0 0</pose>
        <geometry>
          <box>
            <size>0.02001 0.24 0.01</size>
          </box>
        </geometry>
        <material>
          <ambient>0.8706 0.7216 0.5294 1.0</ambient>
          <diffuse>0.8706 0.7216 0.5294 1.0</diffuse>
        </material>
      </visual>
      <visual name="chassis_front_face_top_marker">
        <pose>0.245 0 0.1325 0 0 0</pose>
        <geometry>
          <box>
            <size>0.01 0.12 0.0001</size>
          </box>
        </geometry>
        <material>
          <ambient>0.0 0.7059 0.0 1.0</ambient>
          <diffuse>0.0 0.7059 0.0 1.0</diffuse>
        </material>
      </visual>
      <visual name="chassis_front_face_left">
        <pose>0.24 0.115 0.0725 0 0 0</pose>
        <geometry>
          <box>
            <size>0.02001 0.01 0.12</size>
          </box>
        </geometry>
        <material>
          <ambient>0.8706 0.7216 0.5294 1.0</ambient>
          <diffuse>0.8706 0.7216 0.5294 1.0</diffuse>
        </material>
      </visual>
      <visual name="chassis_front_face_right">
        <pose>0.24 -0.115 0.0725 0 0 0</pose>
        <geometry>
          <box>
            <size>0.02001 0.01 0.12</size>
          </box>
        </geometry>
        <material>
          <ambient>0.8706 0.7216 0.5294 1.0</ambient>
          <diffuse>0.8706 0.7216 0.5294 1.0</diffuse>
        </material>
      </visual>
      <visual name="chassis_rear_face_bottom">
        <pose>-0.24 0 0.0175 0 0 0</pose>
        <geometry>
          <box>
            <size>0.02001 0.24 0.01</size>
          </box>
        </geometry>
        <material>
          <ambient>0.8706 0.7216 0.5294 1.0</ambient>
          <diffuse>0.8706 0.7216 0.5294 1.0</diffuse>
        </material>
      </visual>
      <visual name="chassis_rear_face_top">
        <pose>-0.24 0 0.1275 0 0 0</pose>
        <geometry>
          <box>
            <size>0.02001 0.24 0.01</size>
          </box>
        </geometry>
        <material>
          <ambient>0.8706 0.7216 0.5294 1.0</ambient>
          <diffuse>0.8706 0.7216 0.5294 1.0</diffuse>
        </material>
      </visual>
      <visual name="chassis_rear_face_top_marker">
        <pose>-0.245 0 0.1325 0 0 0</pose>
        <geometry>
          <box>
            <size>0.01 0.12 0.0001</size>
          </box>
        </geometry>
        <material>
          <ambient>0.7059 0.0 0.0 1.0</ambient>
          <diffuse>0.7059 0.0 0.0 1.0</diffuse>
        </material>
      </visual>
      <visual name="chassis_rear_face_left">
        <pose>-0.24 0.115 0.0725 0 0 0</pose>
        <geometry>
          <box>
            <size>0.02001 0.01 0.12</size>
          </box>
        </geometry>
        <material>
          <ambient>0.8706 0.7216 0.5294 1.0</ambient>
          <diffuse>0.8706 0.7216 0.5294 1.0</diffuse>
        </material>
      </visual>
      <visual name="chassis_rear_face_right">
        <pose>-0.24 -0.115 0.0725 0 0 0</pose>
        <geometry>
          <box>
            <size>0.02001 0.01 0.12</size>
          </box>
        </geometry>
        <material>
          <ambient>0.8706 0.7216 0.5294 1.0</ambient>
          <diffuse>0.8706 0.7216 0.5294 1.0</diffuse>
        </material>
      </visual>
      <visual name="lidar_base_visual">
        <pose>0 0 0.135 0 0 0</pose>
        <geometry>
          <box>
            <size>0.3001 0.21 0.005</size>
          </box>
        </geometry>
        <material>
          <ambient>0.8706 0.7216 0.5294 1.0</ambient>
          <diffuse>0.8706 0.7216 0.5294 1.0</diffuse>
        </material>
      </visual> -->
      <!-- <visual name="cable_cover_left_visual">
        <pose>0 0.095 0.1475 0 0 0</pose>
        <geometry>
          <box>
            <size>0.07 0.02 0.02001</size>
          </box>
        </geometry>
        <material>
          <ambient>0.8706 0.7216 0.5294 1.0</ambient>
          <diffuse>0.8706 0.7216 0.5294 1.0</diffuse>
        </material>
      </visual>
      <visual name="cable_cover_right_visual">
        <pose>0 -0.095 0.1475 0 0 0</pose>
        <geometry>
          <box>
            <size>0.07 0.02 0.02001</size>
          </box>
        </geometry>
        <material>
          <ambient>0.8706 0.7216 0.5294 1.0</ambient>
          <diffuse>0.8706 0.7216 0.5294 1.0</diffuse>
        </material>
      </visual>
      <visual name="cable_cover_top_visual">
        <pose>0 0.0 0.16 0 0 0</pose>
        <geometry>
          <box>
            <size>0.07 0.21 0.005</size>
          </box>
        </geometry>
        <material>
          <ambient>0.8706 0.7216 0.5294 1.0</ambient>
          <diffuse>0.8706 0.7216 0.5294 1.0</diffuse>
        </material>
      </visual> -->
      <collision name="left_mount_collision">
        <pose>0.0 0.17 0.085 0 0 0</pose>
        <geometry>
          <box>
            <size>0.08 0.1 0.115</size>
          </box>
        </geometry>
      </collision>
      <!-- <visual name="left_mount_visual">
        <pose>0.0 0.17 0.0725 0 0 0</pose>
        <geometry>
          <box>
            <size>0.08 0.1 0.09</size>
          </box>
        </geometry>
        <material>
          <ambient>0.8706 0.7216 0.5294 1.0</ambient>
          <diffuse>0.8706 0.7216 0.5294 1.0</diffuse>
        </material>
      </visual>
      <visual name="left_mount_top_marker_visual">
        <pose>0.0 0.215 0.1175 0 0 0</pose>
        <geometry>
          <box>
            <size>0.08 0.01 0.0001</size>
          </box>
        </geometry>
        <material>
          <ambient>0.0 0.0 0.7059 1.0</ambient>
          <diffuse>0.0 0.0 0.7059 1.0</diffuse>
        </material>
      </visual> -->
      <collision name="right_mount_collision">
        <pose>0.0 -0.17 0.085 0 0 0</pose>
        <geometry>
          <box>
            <size>0.08 0.1 0.115</size>
          </box>
        </geometry>
      </collision>
      <!-- <visual name="right_mount_visual">
        <pose>0.0 -0.17 0.0725 0 0 0</pose>
        <geometry>
          <box>
            <size>0.08 0.1 0.09</size>
          </box>
        </geometry>
        <material>
          <ambient>0.8706 0.7216 0.5294 1.0</ambient>
          <diffuse>0.8706 0.7216 0.5294 1.0</diffuse>
        </material>
      </visual>
      <visual name="right_mount_top_marker_visual">
        <pose>0.0 -0.215 0.1175 0 0 0</pose>
        <geometry>
          <box>
            <size>0.08 0.01 0.0001</size>
          </box>
        </geometry>
        <material>
          <ambient>0.8627 0.8627 0.0 1.0</ambient>
          <diffuse>0.8627 0.8627 0.0 1.0</diffuse>
        </material>
      </visual>
      <visual name="emergency_stop_bottom_visual">
        <pose>0.0 -0.155 0.125 0 0 0</pose>
        <geometry>
          <cylinder>
            <length>0.015</length>
            <radius>0.015</radius>
          </cylinder>
        </geometry>
        <material>
          <ambient>0.7059 0.7059 0.7059 1.0</ambient>
          <diffuse>0.7059 0.7059 0.7059 1.0</diffuse>
        </material>
      </visual>
      <visual name="emergency_stop_top_visual">
        <pose>0.0 -0.155 0.135 0 0 0</pose>
        <geometry>
          <cylinder>
            <length>0.005</length>
            <radius>0.02</radius>
          </cylinder>
        </geometry>
        <material>
          <ambient>1.0 0.0 0.0 1.0</ambient>
          <diffuse>1.0 0.0 0.0 1.0</diffuse>
        </material>
      </visual>
      <visual name="power_switch_bottom_visual">
        <pose>0.0 0.155 0.1225 0 0 0</pose>
        <geometry>
          <cylinder>
            <length>0.005</length>
            <radius>0.015</radius>
          </cylinder>
        </geometry>
        <material>
          <ambient>0.0 0.0 0.0 1.0</ambient>
          <diffuse>0.0 0.0 0.0 1.0</diffuse>
        </material>
      </visual>
      <visual name="power_switch_middle_visual">
        <pose>0.0 0.155 0.1275 0 0 0</pose>
        <geometry>
          <cylinder>
            <length>0.005</length>
            <radius>0.015</radius>
          </cylinder>
        </geometry>
        <material>
          <ambient>0.7059 0.7059 0.7059 1.0</ambient>
          <diffuse>0.7059 0.7059 0.7059 1.0</diffuse>
        </material>
      </visual>
      <visual name="power_switch_top_visual">
        <pose>0.0 0.155 0.1375 0 0 0.35</pose>
        <geometry>
          <box>
            <size>0.025 0.005 0.01</size>
          </box>
        </geometry>
        <material>
          <ambient>0.0 0.0 0.0 1.0</ambient>
          <diffuse>0.0 0.0 0.0 1.0</diffuse>
        </material>
      </visual>
      <visual name="wheel_mount_front_left_axis_visual">
        <pose>0.19 0.11 0 1.5707963267948966 0 0</pose>
        <geometry>
          <cylinder>
            <length>0.05</length>
            <radius>0.008</radius>
          </cylinder>
        </geometry>
        <material>
          <ambient>0.0 0.0 0.0 1.0</ambient>
          <diffuse>0.0 0.0 0.0 1.0</diffuse>
        </material>
      </visual>
      <visual name="wheel_mount_front_left_visual">
        <pose>0.19 0.08 0 0 0 0</pose>
        <geometry>
          <box>
            <size>0.05 0.07 0.025</size>
          </box>
        </geometry>
        <material>
          <ambient>0.502 0.502 0.502 1.0</ambient>
          <diffuse>0.502 0.502 0.502 1.0</diffuse>
        </material>
      </visual>
      <visual name="wheel_mount_front_right_axis_visual">
        <pose>0.19 -0.11 0 1.5707963267948966 0 0</pose>
        <geometry>
          <cylinder>
            <length>0.05</length>
            <radius>0.008</radius>
          </cylinder>
        </geometry>
        <material>
          <ambient>0.0 0.0 0.0 1.0</ambient>
          <diffuse>0.0 0.0 0.0 1.0</diffuse>
        </material>
      </visual>
      <visual name="wheel_mount_front_right_visual">
        <pose>0.19 -0.08 0 0 0 0</pose>
        <geometry>
          <box>
            <size>0.05 0.07 0.025</size>
          </box>
        </geometry>
        <material>
          <ambient>0.502 0.502 0.502 1.0</ambient>
          <diffuse>0.502 0.502 0.502 1.0</diffuse>
        </material>
      </visual>
      <visual name="wheel_mount_rear_left_axis_visual">
        <pose>-0.19 0.11 0 1.5707963267948966 0 0</pose>
        <geometry>
          <cylinder>
            <length>0.05</length>
            <radius>0.008</radius>
          </cylinder>
        </geometry>
        <material>
          <ambient>0.0 0.0 0.0 1.0</ambient>
          <diffuse>0.0 0.0 0.0 1.0</diffuse>
        </material>
      </visual>
      <visual name="wheel_mount_rear_left_visual">
        <pose>-0.19 0.08 0 0 0 0</pose>
        <geometry>
          <box>
            <size>0.05 0.07 0.025</size>
          </box>
        </geometry>
        <material>
          <ambient>0.502 0.502 0.502 1.0</ambient>
          <diffuse>0.502 0.502 0.502 1.0</diffuse>
        </material>
      </visual>
      <visual name="wheel_mount_rear_right_axis_visual">
        <pose>-0.19 -0.11 0 1.5707963267948966 0 0</pose>
        <geometry>
          <cylinder>
            <length>0.05</length>
            <radius>0.008</radius>
          </cylinder>
        </geometry>
        <material>
          <ambient>0.0 0.0 0.0 1.0</ambient>
          <diffuse>0.0 0.0 0.0 1.0</diffuse>
        </material>
      </visual>
      <visual name="wheel_mount_rear_right_visual">
        <pose>-0.19 -0.08 0 0 0 0</pose>
        <geometry>
          <box>
            <size>0.05 0.07 0.025</size>
          </box>
        </geometry>
        <material>
          <ambient>0.502 0.502 0.502 1.0</ambient>
          <diffuse>0.502 0.502 0.502 1.0</diffuse>
        </material>
      </visual> -->
    </link>

    <link name="front_left_wheel">
      <pose>0.19 0.19 0 0 0 0</pose>
      <!-- Inertia approximated by a solid cylinder of a smaller diameter
           than the whole wheel and almost full width (r=0.1, h=0.08),
           because most of the mass is is the hub motor, which is
           surrounded by air tire. -->
      <inertial>
        <mass>5.0</mass>
        <inertia>
          <ixx>0.0153</ixx>
          <iyy>0.025</iyy>
          <izz>0.0153</izz>
        </inertia>
      </inertial>
      <collision name="front_left_wheel_collision">
        <pose>0 0 0 -1.5707963267948966 0 0</pose>
        <geometry>
          <cylinder>
            <length>0.082</length>
            <radius>0.1275</radius>
          </cylinder>
        </geometry>
        <surface>
          <friction>
            <ode>
              <mu>0.5</mu>
              <mu2>1</mu2>
              <slip1>0.0016</slip1>
              <slip2>0</slip2>
              <fdir1>0 0 1</fdir1>
            </ode>
          </friction>
        </surface>
      </collision>
      <visual name="front_left_wheel_tire_visual">
        <pose>0 0 0 1.5708 0 0</pose>
        <geometry>
          <mesh>
            <uri>meshes/wheel_left.dae</uri>
            <scale>1.3010204 1.3010204 2.05</scale>
          </mesh>
        </geometry>
      </visual>
      <visual name="front_left_wheel_hub_visual">
        <pose>0 -0.055 0 1.5707963267948966 0 0</pose>
        <geometry>
          <cylinder>
            <length>0.025</length>
            <radius>0.04</radius>
          </cylinder>
        </geometry>
        <material>
          <ambient>0.502 0.502 0.502 1.0</ambient>
          <diffuse>0.502 0.502 0.502 1.0</diffuse>
        </material>
      </visual>
    </link>

    <link name="front_right_wheel">
      <pose>0.19 -0.19 0 0 0 0</pose>
      <inertial>
        <mass>5.0</mass>
        <inertia>
          <ixx>0.0153</ixx>
          <iyy>0.025</iyy>
          <izz>0.0153</izz>
        </inertia>
      </inertial>
      <collision name="front_right_wheel_collision">
        <pose>0 0 0 1.5707963267948966 0 0</pose>
        <geometry>
          <cylinder>
            <length>0.082</length>
            <radius>0.1275</radius>
          </cylinder>
        </geometry>
        <surface>
          <friction>
            <ode>
              <mu>0.5</mu>
              <mu2>1</mu2>
              <slip1>0.0016</slip1>
              <slip2>0</slip2>
              <fdir1>0 0 1</fdir1>
            </ode>
          </friction>
        </surface>
      </collision>
      <visual name="front_right_wheel_tire_visual">
        <pose>0 0 0 1.5708 0 0</pose>
        <geometry>
          <mesh>
            <uri>meshes/wheel_right.dae</uri>
            <scale>1.3010204 1.3010204 2.05</scale>
          </mesh>
        </geometry>
      </visual>
      <visual name="front_right_wheel_hub_visual">
        <pose>0 0.055 0 1.5707963267948966 0 0</pose>
        <geometry>
          <cylinder>
            <length>0.025</length>
            <radius>0.04</radius>
          </cylinder>
        </geometry>
        <material>
          <ambient>0.502 0.502 0.502 1.0</ambient>
          <diffuse>0.502 0.502 0.502 1.0</diffuse>
        </material>
      </visual>
    </link>

    <link name="rear_left_wheel">
      <pose>-0.19 0.19 0 0 0 0</pose>
      <inertial>
        <mass>5.0</mass>
        <inertia>
          <ixx>0.0153</ixx>
          <iyy>0.025</iyy>
          <izz>0.0153</izz>
        </inertia>
      </inertial>
      <collision name="rear_left_wheel_collision">
        <pose>0 0 0 -1.5707963267948966 0 0</pose>
        <geometry>
          <cylinder>
            <length>0.082</length>
            <radius>0.1275</radius>
          </cylinder>
        </geometry>
        <surface>
          <friction>
            <ode>
              <mu>0.5</mu>
              <mu2>1</mu2>
              <slip1>0.0016</slip1>
              <slip2>0</slip2>
              <fdir1>0 0 1</fdir1>
            </ode>
          </friction>
        </surface>
      </collision>
      <visual name="rear_left_wheel_tire_visual">
        <pose>0 0 0 1.5708 0 0</pose>
        <geometry>
          <mesh>
            <uri>meshes/wheel_left.dae</uri>
            <scale>1.3010204 1.3010204 2.05</scale>
          </mesh>
        </geometry>
      </visual>
      <visual name="rear_left_wheel_hub_visual">
        <pose>0 -0.055 0 1.5707963267948966 0 0</pose>
        <geometry>
          <cylinder>
            <length>0.025</length>
            <radius>0.04</radius>
          </cylinder>
        </geometry>
        <material>
          <ambient>0.502 0.502 0.502 1.0</ambient>
          <diffuse>0.502 0.502 0.502 1.0</diffuse>
        </material>
      </visual>
    </link>

    <link name="rear_right_wheel">
      <pose>-0.19 -0.19 0 0 0 0</pose>
      <inertial>
        <mass>5.0</mass>
        <inertia>
          <ixx>0.0153</ixx>
          <iyy>0.025</iyy>
          <izz>0.0153</izz>
        </inertia>
      </inertial>
      <collision name="rear_right_wheel_collision">
        <pose>0 0 0 1.5707963267948966 0 0</pose>
        <geometry>
          <cylinder>
            <length>0.082</length>
            <radius>0.1275</radius>
          </cylinder>
        </geometry>
        <surface>
          <friction>
            <ode>
              <mu>0.5</mu>
              <mu2>1</mu2>
              <slip1>0.0016</slip1>
              <slip2>0</slip2>
              <fdir1>0 0 1</fdir1>
            </ode>
          </friction>
        </surface>
      </collision>
      <visual name="rear_right_wheel_tire_visual">
        <pose>0 0 0 1.5708 0 0</pose>
        <geometry>
          <mesh>
            <uri>meshes/wheel_right.dae</uri>
            <scale>1.3010204 1.3010204 2.05</scale>
          </mesh>
        </geometry>
      </visual>
      <visual name="rear_right_wheel_hub_visual">
        <pose>0 0.055 0 1.5707963267948966 0 0</pose>
        <geometry>
          <cylinder>
            <length>0.025</length>
            <radius>0.04</radius>
          </cylinder>
        </geometry>
        <material>
          <ambient>0.502 0.502 0.502 1.0</ambient>
          <diffuse>0.502 0.502 0.502 1.0</diffuse>
        </material>
      </visual>
    </link>

    <!-- 4x 500W hub motor with ~30 km/h maximum speed.
         However, we operate them with a speed and torque limit
         in software.
         https://www.uumotor.com/10-inch-single-shaft-brushless-motor-sensorless.html
    -->
    <joint name="front_left_wheel_joint" type="revolute">
      <child>front_left_wheel</child>
      <parent>base_link</parent>
      <axis>
        <xyz>0 1 0</xyz>
        <limit>
          <lower>-1.79769e+308</lower>
          <upper>+1.79769e+308</upper>
          <!-- 2.5 m/s => angular velocity of the wheel in rad/s -->
          <velocity>19.61</velocity>
          <!-- Torque in NM. -->
          <effort>10</effort>
        </limit>
        <use_parent_model_frame>1</use_parent_model_frame>
      </axis>
    </joint>

    <joint name="rear_left_wheel_joint" type="revolute">
      <parent>base_link</parent>
      <child>rear_left_wheel</child>
      <axis>
        <xyz>0 1 0</xyz>
        <limit>
          <lower>-1.79769e+308</lower>
          <upper>+1.79769e+308</upper>
          <!-- 2.5 m/s => angular velocity of the wheel in rad/s -->
          <velocity>19.61</velocity>
          <!-- Torque in NM. -->
          <effort>10</effort>
        </limit>
      </axis>
    </joint>

    <joint name="rear_right_wheel_joint" type="revolute">
      <parent>base_link</parent>
      <child>rear_right_wheel</child>
      <axis>
        <xyz>0 1 0</xyz>
        <limit>
          <lower>-1.79769e+308</lower>
          <upper>+1.79769e+308</upper>
          <!-- 2.5 m/s => angular velocity of the wheel in rad/s -->
          <velocity>19.61</velocity>
          <!-- Torque in NM. -->
          <effort>10</effort>
        </limit>
      </axis>
    </joint>

    <joint name="front_right_wheel_joint" type="revolute">
      <parent>base_link</parent>
      <child>front_right_wheel</child>
      <axis>
        <xyz>0 1 0</xyz>
        <limit>
          <lower>-1.79769e+308</lower>
          <upper>+1.79769e+308</upper>
          <!-- 2.5 m/s => angular velocity of the wheel in rad/s -->
          <velocity>19.61</velocity>
          <!-- Torque in NM. -->
          <effort>10</effort>
        </limit>
      </axis>
    </joint>

    <plugin name="differential_drive_controller" filename="libgazebo_ros_diff_drive.so">
        <!-- Plugin update rate in Hz -->
        <updateRate>20</updateRate>
        <!-- Name of left joint, defaults to `left_joint` -->
        <leftJoint>front_left_wheel_joint</leftJoint>
        <!-- Name of right joint, defaults to `right_joint` -->
        <rightJoint>front_right_wheel_joint</rightJoint>
        <!-- The distance from the center of one wheel to the other, in meters, defaults to 0.34 m -->
        <wheelSeparation>0.26</wheelSeparation>
        <!-- Diameter of the wheels, in meters, defaults to 0.15 m -->
        <wheelDiameter>0.255</wheelDiameter>
        <!-- Wheel acceleration, in rad/s^2, defaults to 0.0 rad/s^2 -->
        <wheelAcceleration>1.0</wheelAcceleration>
        <!-- Maximum torque which the wheels can produce, in Nm, defaults to 5 Nm -->
        <wheelTorque>20</wheelTorque>
        <!-- Topic to receive geometry_msgs/Twist message commands, defaults to `cmd_vel` -->
        <commandTopic>cmd_vel</commandTopic>
        <!-- Topic to publish nav_msgs/Odometry messages, defaults to `odom` -->
        <odometryTopic>odom</odometryTopic>
        <!-- Odometry frame, defaults to `odom` -->
        <odometryFrame>odom</odometryFrame>
        <!-- Robot frame to calculate odometry from, defaults to `base_footprint` -->
        <robotBaseFrame>base_footprint</robotBaseFrame>
        <!-- Odometry source, 0 for ENCODER, 1 for WORLD, defaults to WORLD -->
        <odometrySource>1</odometrySource>
        <!-- Set to true to publish transforms for the wheel links, defaults to false -->
        <publishWheelTF>true</publishWheelTF>
        <!-- Set to true to publish transforms for the odometry, defaults to true -->
        <publishOdom>true</publishOdom>
        <!-- Set to true to publish sensor_msgs/JointState on /joint_states for the wheel joints, defaults to false -->
        <publishWheelJointState>true</publishWheelJointState>
        <!-- Set to true to swap right and left wheels, defaults to true -->
        <legacyMode>false</legacyMode>
    </plugin>

  </model>
</sdf>
